Workbook
Name Add_on_Promotion: '[1]Dropdown list'!$H$2:$H$4
Name Campaign_Tiering: 'Dropdown list'!$C$2:$C$7
Name Combobuy: 'Dropdown list'!$Q$2:$Q$6
Name CPD: 'Dropdown list'!$M$26:$M$28
Name CPD_Brands: 'Dropdown list'!$M$26:$M$28
Name DealCriteria: 'Dropdown list'!$S$2:$S$4
Name FixedPrice: 'Dropdown list'!$R$2:$R$3
Name FlexiComboMechanics: 'Dropdown list'!$L$2:$L$6
Name Freegiftorsample: 'Dropdown list'!$P$2:$P$5
Name LDB: 'Dropdown list'!$Q$26:$Q$29
Name LDB_Brands: 'Dropdown list'!$Q$26:$Q$29
Name LLD: 'Dropdown list'!$P$26:$P$30
Name LLD_Brands: 'Dropdown list'!$P$26:$P$30
Name Member_Group: 'Dropdown list'!$H$2:$H$6
Name MoneyorDiscount: 'Dropdown list'!$N$2:$N$4
Name NA: 'Dropdown list'!$K$2:$K$3
Name Platform: 'Dropdown list'!$B$2:$B$4
Name PPD: 'Dropdown list'!$N$26:$N$27
Name PPD_Brands: 'Dropdown list'!$N$26:$N$27
Name Reward_Setting: '[1]Dropdown list'!$Q$2:$Q$4
Name SIS_Time_slot: 'Dropdown list'!$T$2:$T$8
Name StorewidevsSpecific: 'Dropdown list'!$M$2:$M$4
Name Type_of_Add_on_Promotion: 'Dropdown list'!$J$2:$J$4
Name Type_of_Mechanics: 'Dropdown list'!$I$2:$I$2
Name Type_of_Members: 'Dropdown list'!$G$2:$G$4
Name Voucher_Discount_Type: '[1]Dropdown list'!$R$2:$R$4
Name Voucher_Type: 'Dropdown list'!$D$2:$D$7
Name DealCriteria: '[2]Dropdown list'!$O$2:$O$4
Name NA: '[2]Dropdown list'!$H$2:$H$3
Name SIS_Time_slot: '[2]Dropdown list'!$P$2:$P$8
Name StorewidevsSpecific: '[2]Dropdown list'!$J$2:$J$4
Name DealCriteria: '[2]Dropdown list'!$O$2:$O$4
Name NA: '[2]Dropdown list'!$H$2:$H$3
Name SIS_Time_slot: '[2]Dropdown list'!$P$2:$P$8
Name StorewidevsSpecific: '[2]Dropdown list'!$J$2:$J$4
Name DealCriteria: '[2]Dropdown list'!$O$2:$O$4
Name NA: '[2]Dropdown list'!$H$2:$H$3
Name SIS_Time_slot: '[2]Dropdown list'!$P$2:$P$8
Name StorewidevsSpecific: '[2]Dropdown list'!$J$2:$J$4

Sheet Open Points
A1: S. No. | B1: Query Date | C1: Division | D1: Brand | E1: Archetype | F1: Platform | G1: Query raised by | H1: Role | I1: Query Details | J1: Query Status | K1: Query to | L1: Query Resolution Details | M1: Resolution Date | N1: Learning Shared with the Team Yes/No | O1: Comments if any
B2: (Date) | C2: (CPD/PPD/ LLD/ACD) | E2: (MP) | F2: (Shopee, Lazada) | G2: Name | H2: (E-shop, E-merch, etc.) | I2: (Add details/context to the query) | J2: (Open/Closed) | K2: (Name of the person to whom the query is addressed | L2: (Response recorded from Loreal)
A3: 1 | B3: 45166 | C3: LDB | D3: All | E3: MP | F3: Lazada | G3: Nikhil S | I3: Brand membership --> Type of mechanic Is New Member Voucher same as Welcome - voucher? | J3: Closed | K3: LDB
A4: 2 | B4: 45166 | C4: LDB | D4: All | E4: MP | F4: Lazada | G4: Nikhil S | I4: Brand membership --> Type of mechanic What is the Name of the points reedemable voucher on seller central? | J4: Open | K4: LDB
A5: 3 | B5: 45166 | C5: LDB | D5: All | E5: MP | F5: Lazada | G5: Nikhil S | I5: Brand membership --> Type of mechanic Is member exclusive voucher same as linked member voucher If different How does this work? | J5: Closed | K5: LDB
A6: 4 | B6: 45166 | C6: LDB | D6: All | E6: MP | F6: Lazada | G6: Nikhil S | I6: Brand membership --> Type of mechanic Is new member product offer same as linked member product offer if different How does this work? | J6: Closed | K6: LDB
A7: 5 | B7: 45167 | C7: LDB | D7: All | E7: MP | F7: Lazada | G7: Nikhil S | I7: Do we have to replicate the CEM structure that client has shared? | J7: Closed
A8: 6 | B8: 45167 | C8: LDB | D8: All | E8: MP | F8: Lazada | G8: Nikhil S | I8: Should we replicate the structure of visual template shared by the LDB team as is? Need clarity on how to read the LDB Artwork briefing template shared? | J8: Closed
A9: 7 | B9: 45167 | C9: LDB | D9: All | E9: MP | F9: Lazada | G9: Nikhil S | I9: Flash sale should be separate tab or should be part of the Price change (TB)? | J9: Closed
A10: 8 | B10: 45167 | C10: LDB | D10: All | E10: MP | F10: Lazada | G10: Nikhil S | I10: Add LZD in the tab names | J10: Closed | K10: Nikhil
A11: 9 | B11: 45167 | C11: LDB | D11: All | E11: MP | F11: Lazada | G11: Nikhil S | I11: Do we need a separate tab for VB? | J11: Closed | K11: Nicha
A12: 10 | B12: 45167 | C12: LDB | D12: All | E12: MP | F12: Lazada | G12: Nikhil S | I12: Need to check brand list and make it nested list | J12: Closed | K12: Nikhil
A13: 11 | B13: 45167 | C13: LDB | D13: All | E13: MP | F13: Lazada | G13: Nikhil S | I13: What are the date columns that we need for Launch Requirement GWP sheet | J13: Closed | K13: Hafizah
A14: 12 | B14: 45167 | C14: LDB | D14: All | E14: MP | F14: Lazada | G14: Nikhil S | I14: Is current price an optional field for Price change (TB) - LZD? | J14: Closed | K14: Hafizah
A15: 13 | B15: 45167 | C15: LDB | D15: All | E15: MP | F15: Lazada | G15: Nikhil S | I15: Is order limit same as total number of offers | J15: Closed | K15: Hafizah
A16: 14 | B16: 45167 | C16: LDB | D16: All | E16: MP | F16: Lazada | G16: Nikhil S | I16: Confirm Skin C brand division | J16: Closed | K16: Hafizah
A17: 15 | B17: 45167 | C17: LDB | D17: All | E17: MP | F17: Lazada | G17: Nikhil S | I17: Start time and end time are mandatory for all promotion? | J17: Closed | K17: Hafizah

Sheet Touchless
A1: Fields | B1: Values | C1: Tool Tips | D1: Comments
A2: Archetype | B2: Marketplace | C2: Select Archetype | D2: Archetype selected should be same as the one selected in CXL request flow
A3: Market | B3: Lazada | C3: Select Market
A4: Country | B4: Malaysia | C4: Select Country Based on the Market Selected
A5: Country | C5: Select Country Based on the Market Selected
A6: Division | B6: L’Oréal Luxe Division (LLD) | C6: Select Business Division
A7: Brands | B7: Shu Uemura | C7: Select Brands | D7: Provide atleast one value for the Brands to be included in the Request and provide multiple brands only if applicable or else leave the other brand fields as blank
A8: Brands | C8: Select Brands
A9: Brands | C9: Select Brands
A10: Brands | C10: Select Brands
A11: Brands | C11: Select Brands
A12: Brands | C12: Select Brands
A13: Brands | C13: Select Brands
A14: Brands | C14: Select Brands
A15: Brands | C15: Select Brands
A16: Brands | C16: Select Brands
A17: Request Type | B17: Campaign Management | C17: Select Request Type | D17: Please select relevant Request type if applicable oe else select "Not Applicable"
A18: Request Sub type | B18: Others | C18: Select Reqquest Sub Type | D18: Please select relevant Request Sub type if applicable oe else select "Not Applicable"
A19: Platform | C19: Select Platforms | D19: Provide atleast one value for the Platforms to be included in the Request and provide multiple brands only if applicable or else leave the other Platform fields as blank
A20: Platform | C20: Select Platforms
A21: Platform | C21: Select Platforms
A22: Delivery Date | C22: Enter the Delivery Date and Time | D22: Enter the Delivery date and press enter and then select the relevant time. If Time value is not provided then Default value of "0:00" will be selected
A23: Live Date | C23: Enter the Live Launch Date and Time | D23: Enter the Live date and press enter and then select the relevant time. If Time value is not provided then Default value of "0:00" will be selected

Sheet RGM
A1: BRAND | B1: SKU ID Shopee | C1: PID | D1: SID | E1: Barcode | F1: Product Name | G1: Status | H1: Variant | I1: RGM Code Mapping | J1: PRICE 2024 | K1: BAU | L1: BMO BAU | M1: FS BAU | N1: BRAND | O1: BMO BRAND | P1: FS BRAND | Q1: PLATFORM | R1: BMO PLATFORM | S1: FS PLATFORM | T1: >>> | V1: BAU | W1: BMO BAU | X1: FS BAU | Y1: BRAND | Z1: BMO BRAND | AA1: FS BRAND | AB1: PLATFORM | AC1: BMO PLATFORM | AD1: FS PLATFORM
A2: MYB | B2: 7150202805_ID-13461816795 | C2: =_xlfn.NUMBERVALUE(LEFT(B2,10)) | D2: =_xlfn.NUMBERVALUE(RIGHT(B2,11)) | E2: 8991380011170 | F2: Maybelline Define And Blend Mechanic Eyebrow Pencil Make up - 17gr (Pensil Alis Untuk Alis Tampak Tebal & Natural) | J2: 83900 | K2: 0.2 | L2: 0.25 | M2: 0.26 | N2: 0.21 | O2: 0.26 | P2: 0.27 | Q2: 0.22 | R2: 0.27 | S2: 0.28 | V2: 67200 | W2: 63000 | X2: 62100 | Y2: 66300 | Z2: 62100 | AA2: 61300 | AB2: 65500 | AC2: 61300 | AD2: 60500
A3: MYB | B3: 7150202805_ID-13461594514 | C3: =_xlfn.NUMBERVALUE(LEFT(B3,10)) | D3: =_xlfn.NUMBERVALUE(RIGHT(B3,11)) | E3: 8991380011163 | F3: Maybelline Define And Blend Mechanic Eyebrow Pencil Make up - 17gr (Pensil Alis Untuk Alis Tampak Tebal & Natural) | J3: 83900 | K3: 0.2 | L3: 0.25 | M3: 0.26 | N3: 0.21 | O3: 0.26 | P3: 0.27 | Q3: 0.22 | R3: 0.27 | S3: 0.28 | V3: 67200 | W3: 63000 | X3: 62100 | Y3: 66300 | Z3: 62100 | AA3: 61300 | AB3: 65500 | AC3: 61300 | AD3: 60500
A4: MYB | B4: 7116504754_ID-13418988876 | C4: =_xlfn.NUMBERVALUE(LEFT(B4,10)) | D4: =_xlfn.NUMBERVALUE(RIGHT(B4,11)) | E4: 6902395740353 | F4: Maybelline Line Tattoo High Impact Liner Make Up - 7gr (Eyeliner Hitam Waterproof Tahan Lama Hingga 36 Jam) | J4: 93900 | K4: 0.25 | L4: 0.26 | M4: 0.27 | N4: 0.26 | O4: 0.27 | P4: 0.28 | Q4: 0.27 | R4: 0.28 | S4: 0.29 | V4: 70500 | W4: 69500 | X4: 68600 | Y4: 69500 | Z4: 68600 | AA4: 67700 | AB4: 68600 | AC4: 67700 | AD4: 66700
A5: MYB | B5: 7113822983_ID-13415978652 | C5: =_xlfn.NUMBERVALUE(LEFT(B5,10)) | D5: =_xlfn.NUMBERVALUE(RIGHT(B5,11)) | E5: 6902395830566 | F5: Maybelline Fit Me Fresh Tint - Foundation Tint With Vitamin C And SPF 50 For Fresh & Bright Look Face Make Up | J5: 114900 | K5: 0.15 | L5: 0.16 | M5: 0.19 | N5: 0.2 | O5: 0.205 | P5: 0.22 | Q5: 0.22 | R5: 0.225 | S5: 0.23 | V5: 97700 | W5: 96600 | X5: 93100 | Y5: 92000 | Z5: 91400 | AA5: 89700 | AB5: 89700 | AC5: 89100 | AD5: 88500
A6: MYB | B6: 7113822983_ID-13415978653 | C6: =_xlfn.NUMBERVALUE(LEFT(B6,10)) | D6: =_xlfn.NUMBERVALUE(RIGHT(B6,11)) | E6: 6902395830580 | F6: Maybelline Fit Me Fresh Tint - Foundation Tint With Vitamin C And SPF 50 For Fresh & Bright Look Face Make Up | J6: 114900 | K6: 0.15 | L6: 0.16 | M6: 0.19 | N6: 0.2 | O6: 0.205 | P6: 0.22 | Q6: 0.22 | R6: 0.225 | S6: 0.23 | V6: 97700 | W6: 96600 | X6: 93100 | Y6: 92000 | Z6: 91400 | AA6: 89700 | AB6: 89700 | AC6: 89100 | AD6: 88500
A7: MYB | B7: 7113822983_ID-13415978649 | C7: =_xlfn.NUMBERVALUE(LEFT(B7,10)) | D7: =_xlfn.NUMBERVALUE(RIGHT(B7,11)) | E7: 6902395830528 | F7: Maybelline Fit Me Fresh Tint - Foundation Tint With Vitamin C And SPF 50 For Fresh & Bright Look Face Make Up | J7: 114900 | K7: 0.15 | L7: 0.16 | M7: 0.19 | N7: 0.2 | O7: 0.205 | P7: 0.22 | Q7: 0.22 | R7: 0.225 | S7: 0.23 | V7: 97700 | W7: 96600 | X7: 93100 | Y7: 92000 | Z7: 91400 | AA7: 89700 | AB7: 89700 | AC7: 89100 | AD7: 88500
A8: MYB | B8: 7113822983_ID-13415978650 | C8: =_xlfn.NUMBERVALUE(LEFT(B8,10)) | D8: =_xlfn.NUMBERVALUE(RIGHT(B8,11)) | E8: 6902395830542 | F8: Maybelline Fit Me Fresh Tint - Foundation Tint With Vitamin C And SPF 50 For Fresh & Bright Look Face Make Up | J8: 114900 | K8: 0.15 | L8: 0.16 | M8: 0.19 | N8: 0.2 | O8: 0.205 | P8: 0.22 | Q8: 0.22 | R8: 0.225 | S8: 0.23 | V8: 97700 | W8: 96600 | X8: 93100 | Y8: 92000 | Z8: 91400 | AA8: 89700 | AB8: 89700 | AC8: 89100 | AD8: 88500
A9: MYB | B9: 7113822983_ID-13415978651 | C9: =_xlfn.NUMBERVALUE(LEFT(B9,10)) | D9: =_xlfn.NUMBERVALUE(RIGHT(B9,11)) | E9: 6902395830559 | F9: Maybelline Fit Me Fresh Tint - Foundation Tint With Vitamin C And SPF 50 For Fresh & Bright Look Face Make Up | J9: 114900 | K9: 0.15 | L9: 0.16 | M9: 0.19 | N9: 0.2 | O9: 0.205 | P9: 0.22 | Q9: 0.22 | R9: 0.225 | S9: 0.23 | V9: 97700 | W9: 96600 | X9: 93100 | Y9: 92000 | Z9: 91400 | AA9: 89700 | AB9: 89700 | AC9: 89100 | AD9: 88500
A10: MYB | B10: 7110338143_ID-13411274157 | C10: =_xlfn.NUMBERVALUE(LEFT(B10,10)) | D10: =_xlfn.NUMBERVALUE(RIGHT(B10,11)) | E10: 41554453621 | F10: Maybelline Color Sensational Creamy Mattes Lipstick Make up - 4.2gr (Lipstick Matte Dengan Hasil 2x Lebih Intens) | J10: 88900 | K10: 0.02 | L10: 0.04 | M10: 0.05 | N10: 0.05 | O10: 0.06 | P10: 0.07 | Q10: 0.07 | R10: 0.08 | S10: 0.1 | V10: 87200 | W10: 85400 | X10: 84500 | Y10: 84500 | Z10: 83600 | AA10: 82700 | AB10: 82700 | AC10: 81800 | AD10: 80100
A11: MYB | B11: 7110338143_ID-13411274158 | C11: =_xlfn.NUMBERVALUE(LEFT(B11,10)) | D11: =_xlfn.NUMBERVALUE(RIGHT(B11,11)) | E11: 6902395703891 | F11: Maybelline Color Sensational Creamy Mattes Lipstick Make up - 4.2gr (Lipstick Matte Dengan Hasil 2x Lebih Intens) | J11: 88900 | K11: 0.02 | L11: 0.04 | M11: 0.05 | N11: 0.05 | O11: 0.06 | P11: 0.07 | Q11: 0.07 | R11: 0.08 | S11: 0.1 | V11: 87200 | W11: 85400 | X11: 84500 | Y11: 84500 | Z11: 83600 | AA11: 82700 | AB11: 82700 | AC11: 81800 | AD11: 80100
A12: MYB | B12: 7110338143_ID-13411274159 | C12: =_xlfn.NUMBERVALUE(LEFT(B12,10)) | D12: =_xlfn.NUMBERVALUE(RIGHT(B12,11)) | E12: 6902395780694 | F12: Maybelline Color Sensational Creamy Mattes Lipstick Make up - 4.2gr (Lipstick Matte Dengan Hasil 2x Lebih Intens) | J12: 88900 | K12: 0.02 | L12: 0.04 | M12: 0.05 | N12: 0.05 | O12: 0.06 | P12: 0.07 | Q12: 0.07 | R12: 0.08 | S12: 0.1 | V12: 87200 | W12: 85400 | X12: 84500 | Y12: 84500 | Z12: 83600 | AA12: 82700 | AB12: 82700 | AC12: 81800 | AD12: 80100
A13: MYB | B13: 7110338143_ID-13411274160 | C13: =_xlfn.NUMBERVALUE(LEFT(B13,10)) | D13: =_xlfn.NUMBERVALUE(RIGHT(B13,11)) | E13: 6902395780731 | F13: Maybelline Color Sensational Creamy Mattes Lipstick Make up - 4.2gr (Lipstick Matte Dengan Hasil 2x Lebih Intens) | J13: 88900 | K13: 0.02 | L13: 0.04 | M13: 0.05 | N13: 0.05 | O13: 0.06 | P13: 0.07 | Q13: 0.07 | R13: 0.08 | S13: 0.1 | V13: 87200 | W13: 85400 | X13: 84500 | Y13: 84500 | Z13: 83600 | AA13: 82700 | AB13: 82700 | AC13: 81800 | AD13: 80100
... A15: MYB | B15: 7110338143_ID-13411274162 | C15: =_xlfn.NUMBERVALUE(LEFT(B15,10)) | D15: =_xlfn.NUMBERVALUE(RIGHT(B15,11)) | E15: 6902395780809 | F15: Maybelline Color Sensational Creamy Mattes Lipstick Make up - 4.2gr (Lipstick Matte Dengan Hasil 2x Lebih Intens) | J15: 88900 | K15: 0.02 | L15: 0.04 | M15: 0.05 | N15: 0.05 | O15: 0.06 | P15: 0.07 | Q15: 0.07 | R15: 0.08 | S15: 0.1 | V15: 87200 | W15: 85400 | X15: 84500 | Y15: 84500 | Z15: 83600 | AA15: 82700 | AB15: 82700 | AC15: 81800 | AD15: 80100
A16: MYB | B16: 7109298970_ID-13409868601 | C16: =_xlfn.NUMBERVALUE(LEFT(B16,10)) | D16: =_xlfn.NUMBERVALUE(RIGHT(B16,11)) | E16: 6902395685746 | J16: 0 | K16: 0.15 | L16: 0.17 | M16: 0.2 | N16: 0.2 | O16: 0.21 | P16: 0.22 | Q16: 0.22 | R16: 0.23 | S16: 0.24 | V16: 0 | W16: 0 | X16: 0 | Y16: 0 | Z16: 0 | AA16: 0 | AB16: 0 | AC16: 0 | AD16: 0
A17: MYB | B17: 7109298970_ID-13409868600 | C17: =_xlfn.NUMBERVALUE(LEFT(B17,10)) | D17: =_xlfn.NUMBERVALUE(RIGHT(B17,11)) | E17: 6902395685715 | F17: Maybelline Superstay 24Hr Full Coverage Liquid Foundarion Make Up - 30ml (Foundation Matte Cair Tahan Lama Hingga 24 Jam) | J17: 0 | K17: 0.15 | L17: 0.17 | M17: 0.2 | N17: 0.2 | O17: 0.21 | P17: 0.22 | Q17: 0.22 | R17: 0.23 | S17: 0.24 | V17: 0 | W17: 0 | X17: 0 | Y17: 0 | Z17: 0 | AA17: 0 | AB17: 0 | AC17: 0 | AD17: 0
A18: MYB | B18: 7109298970_ID-13409868599 | C18: =_xlfn.NUMBERVALUE(LEFT(B18,10)) | D18: =_xlfn.NUMBERVALUE(RIGHT(B18,11)) | E18: 6902395685708 | F18: Maybelline Superstay 24Hr Full Coverage Liquid Foundarion Make Up - 30ml (Foundation Matte Cair Tahan Lama Hingga 24 Jam) | J18: 0 | K18: 0.15 | L18: 0.17 | M18: 0.2 | N18: 0.2 | O18: 0.21 | P18: 0.22 | Q18: 0.22 | R18: 0.23 | S18: 0.24 | V18: 0 | W18: 0 | X18: 0 | Y18: 0 | Z18: 0 | AA18: 0 | AB18: 0 | AC18: 0 | AD18: 0
A19: MYB | B19: 7109298817_ID-13409848345 | C19: =_xlfn.NUMBERVALUE(LEFT(B19,10)) | D19: =_xlfn.NUMBERVALUE(RIGHT(B19,11)) | E19: 6902395820222 | F19: Maybelline Fit Me Matte + Poreless Cushion Make Up - 14gr (Coverage instant & tahan lama hingga 20 jam) | J19: 265900 | K19: 0.27 | L19: 0.28 | M19: 0.3 | N19: 0.3 | O19: 0.31 | P19: 0.32 | Q19: 0.32 | R19: 0.33 | S19: 0.34 | V19: 194200 | W19: 191500 | X19: 186200 | Y19: 186200 | Z19: 183500 | AA19: 180900 | AB19: 180900 | AC19: 178200 | AD19: 175500
A20: MYB | B20: 7109298817_ID-13409848347 | C20: =_xlfn.NUMBERVALUE(LEFT(B20,10)) | D20: =_xlfn.NUMBERVALUE(RIGHT(B20,11)) | E20: 6902395820277 | F20: Maybelline Fit Me Matte + Poreless Cushion Make Up - 14gr (Coverage instant & tahan lama hingga 20 jam) | J20: 265900 | K20: 0.27 | L20: 0.28 | M20: 0.3 | N20: 0.3 | O20: 0.31 | P20: 0.32 | Q20: 0.32 | R20: 0.33 | S20: 0.34 | V20: 194200 | W20: 191500 | X20: 186200 | Y20: 186200 | Z20: 183500 | AA20: 180900 | AB20: 180900 | AC20: 178200 | AD20: 175500
A21: MYB | B21: 7109298817_ID-13409848346 | C21: =_xlfn.NUMBERVALUE(LEFT(B21,10)) | D21: =_xlfn.NUMBERVALUE(RIGHT(B21,11)) | E21: 6902395820253 | F21: Maybelline Fit Me Matte + Poreless Cushion Make Up - 14gr (Coverage instant & tahan lama hingga 20 jam) | J21: 265900 | K21: 0.27 | L21: 0.28 | M21: 0.3 | N21: 0.3 | O21: 0.31 | P21: 0.32 | Q21: 0.32 | R21: 0.33 | S21: 0.34 | V21: 194200 | W21: 191500 | X21: 186200 | Y21: 186200 | Z21: 183500 | AA21: 180900 | AB21: 180900 | AC21: 178200 | AD21: 175500
A22: MYB | B22: 7109300808_ID-13409832642 | C22: =_xlfn.NUMBERVALUE(LEFT(B22,10)) | D22: =_xlfn.NUMBERVALUE(RIGHT(B22,11)) | E22: 6902395487418 | F22: Maybelline Instant Age Rewind Treatment Concealer Make Up - 60ml (Concealer Cair Untuk Menghapus Lingkaran Hitam Mata) | J22: 155900 | K22: 0.05 | L22: 0.07 | M22: 0.1 | N22: 0.1 | O22: 0.11 | P22: 0.12 | Q22: 0.12 | R22: 0.13 | S22: 0.14 | V22: 148200 | W22: 145000 | X22: 140400 | Y22: 140400 | Z22: 138800 | AA22: 137200 | AB22: 137200 | AC22: 135700 | AD22: 134100
A23: MYB | B23: 7109300808_ID-13409832643 | C23: =_xlfn.NUMBERVALUE(LEFT(B23,10)) | D23: =_xlfn.NUMBERVALUE(RIGHT(B23,11)) | E23: 6902395487425 | F23: Maybelline Instant Age Rewind Treatment Concealer Make Up - 60ml (Concealer Cair Untuk Menghapus Lingkaran Hitam Mata) | J23: 155900 | K23: 0.05 | L23: 0.07 | M23: 0.1 | N23: 0.1 | O23: 0.11 | P23: 0.12 | Q23: 0.12 | R23: 0.13 | S23: 0.14 | V23: 148200 | W23: 145000 | X23: 140400 | Y23: 140400 | Z23: 138800 | AA23: 137200 | AB23: 137200 | AC23: 135700 | AD23: 134100
A24: MYB | B24: 7109300808_ID-13409832640 | C24: =_xlfn.NUMBERVALUE(LEFT(B24,10)) | D24: =_xlfn.NUMBERVALUE(RIGHT(B24,11)) | E24: 6902395748724 | F24: Maybelline Instant Age Rewind Treatment Concealer Make Up - 60ml (Concealer Cair Untuk Menghapus Lingkaran Hitam Mata) | J24: 155900 | K24: 0.05 | L24: 0.07 | M24: 0.1 | N24: 0.1 | O24: 0.11 | P24: 0.12 | Q24: 0.12 | R24: 0.13 | S24: 0.14 | V24: 148200 | W24: 145000 | X24: 140400 | Y24: 140400 | Z24: 138800 | AA24: 137200 | AB24: 137200 | AC24: 135700 | AD24: 134100
A25: MYB | B25: 7109300808_ID-13409832641 | C25: =_xlfn.NUMBERVALUE(LEFT(B25,10)) | D25: =_xlfn.NUMBERVALUE(RIGHT(B25,11)) | E25: 6902395487401 | F25: Maybelline Instant Age Rewind Treatment Concealer Make Up - 60ml (Concealer Cair Untuk Menghapus Lingkaran Hitam Mata) | J25: 155900 | K25: 0.05 | L25: 0.07 | M25: 0.1 | N25: 0.1 | O25: 0.11 | P25: 0.12 | Q25: 0.12 | R25: 0.13 | S25: 0.14 | V25: 148200 | W25: 145000 | X25: 140400 | Y25: 140400 | Z25: 138800 | AA25: 137200 | AB25: 137200 | AC25: 135700 | AD25: 134100
A26: MYB | B26: 7109300808_ID-13409832646 | C26: =_xlfn.NUMBERVALUE(LEFT(B26,10)) | D26: =_xlfn.NUMBERVALUE(RIGHT(B26,11)) | E26: 6902395677376 | F26: Maybelline Instant Age Rewind Treatment Concealer Make Up - 60ml (Concealer Cair Untuk Menghapus Lingkaran Hitam Mata) | J26: 155900 | K26: 0.05 | L26: 0.07 | M26: 0.1 | N26: 0.1 | O26: 0.11 | P26: 0.12 | Q26: 0.12 | R26: 0.13 | S26: 0.14 | V26: 148200 | W26: 145000 | X26: 140400 | Y26: 140400 | Z26: 138800 | AA26: 137200 | AB26: 137200 | AC26: 135700 | AD26: 134100
A27: MYB | B27: 7109300808_ID-13409832644 | C27: =_xlfn.NUMBERVALUE(LEFT(B27,10)) | D27: =_xlfn.NUMBERVALUE(RIGHT(B27,11)) | E27: 6902395487432 | F27: Maybelline Instant Age Rewind Treatment Concealer Make Up - 60ml (Concealer Cair Untuk Menghapus Lingkaran Hitam Mata) | J27: 155900 | K27: 0.05 | L27: 0.07 | M27: 0.1 | N27: 0.1 | O27: 0.11 | P27: 0.12 | Q27: 0.12 | R27: 0.13 | S27: 0.14 | V27: 148200 | W27: 145000 | X27: 140400 | Y27: 140400 | Z27: 138800 | AA27: 137200 | AB27: 137200 | AC27: 135700 | AD27: 134100
A28: MYB | B28: 7109300808_ID-13409832645 | C28: =_xlfn.NUMBERVALUE(LEFT(B28,10)) | D28: =_xlfn.NUMBERVALUE(RIGHT(B28,11)) | E28: 6902395487449 | F28: Maybelline Instant Age Rewind Treatment Concealer Make Up - 60ml (Concealer Cair Untuk Menghapus Lingkaran Hitam Mata) | J28: 155900 | K28: 0.05 | L28: 0.07 | M28: 0.1 | N28: 0.1 | O28: 0.11 | P28: 0.12 | Q28: 0.12 | R28: 0.13 | S28: 0.14 | V28: 148200 | W28: 145000 | X28: 140400 | Y28: 140400 | Z28: 138800 | AA28: 137200 | AB28: 137200 | AC28: 135700 | AD28: 134100
... A693: MYB | B693: 7545130789_ID-13957844057 | C693: =_xlfn.NUMBERVALUE(LEFT(B693,10)) | D693: =_xlfn.NUMBERVALUE(RIGHT(B693,11)) | E693: 8991380035633 | F693: EXCLUSIVE BUNDLE - Maybelline Sky High + Tattoo Liner | J693: 0 | K693: 0.25 | L693: 0.26 | M693: 0.27 | N693: 0.27 | O693: 0.275 | P693: 0.28 | Q693: 0.28 | R693: 0.285 | S693: 0.29 | V693: 0 | W693: 0 | X693: 0 | Y693: 0 | Z693: 0 | AA693: 0 | AB693: 0 | AC693: 0 | AD693: 0
A694: MYB | B694: 7545256453_ID-13957866058 | C694: =_xlfn.NUMBERVALUE(LEFT(B694,10)) | D694: =_xlfn.NUMBERVALUE(RIGHT(B694,11)) | E694: 8991380035640 | J694: 0 | K694: 0.24 | L694: 0.25 | M694: 0.26 | N694: 0.25 | O694: 0.26 | P694: 0.27 | Q694: 0.26 | R694: 0.27 | S694: 0.28 | V694: 0 | W694: 0 | X694: 0 | Y694: 0 | Z694: 0 | AA694: 0 | AB694: 0 | AC694: 0 | AD694: 0
A695: MYB | B695: 7098310224_ID-13971300930 | C695: =_xlfn.NUMBERVALUE(LEFT(B695,10)) | D695: =_xlfn.NUMBERVALUE(RIGHT(B695,11)) | E695: 6902395774211 | F695: Maybelline Fit Me Matte + Poreless Liquid Foundation Make Up 30ml - Makeup Ringan Full Coverage 16HR Oil Control | J695: 171900 | K695: 0.32 | L695: 0.33 | M695: 0.37 | N695: 0.365 | O695: 0.37 | P695: 0.39 | Q695: 0.39 | R695: 0.4 | S695: 0.405 | V695: 116900 | W695: 115200 | X695: 108300 | Y695: 109200 | Z695: 108300 | AA695: 104900 | AB695: 104900 | AC695: 103200 | AD695: 102300
A696: MYB | B696: 7098310224_ID-13971314489 | C696: =_xlfn.NUMBERVALUE(LEFT(B696,10)) | D696: =_xlfn.NUMBERVALUE(RIGHT(B696,11)) | E696: 6902395834403 | F696: Maybelline Fit Me Matte + Poreless Liquid Foundation Make Up 30ml - Makeup Ringan Full Coverage 16HR Oil Control | J696: 171900 | K696: 0.32 | L696: 0.33 | M696: 0.37 | N696: 0.365 | O696: 0.37 | P696: 0.39 | Q696: 0.39 | R696: 0.4 | S696: 0.405 | V696: 116900 | W696: 115200 | X696: 108300 | Y696: 109200 | Z696: 108300 | AA696: 104900 | AB696: 104900 | AC696: 103200 | AD696: 102300
A697: MYB | B697: 7098310224_ID-13971316527 | C697: =_xlfn.NUMBERVALUE(LEFT(B697,10)) | D697: =_xlfn.NUMBERVALUE(RIGHT(B697,11)) | E697: 6902395774297 | F697: Maybelline Fit Me Matte + Poreless Liquid Foundation Make Up 30ml - Makeup Ringan Full Coverage 16HR Oil Control | J697: 171900 | K697: 0.32 | L697: 0.33 | M697: 0.37 | N697: 0.365 | O697: 0.37 | P697: 0.39 | Q697: 0.39 | R697: 0.4 | S697: 0.405 | V697: 116900 | W697: 115200 | X697: 108300 | Y697: 109200 | Z697: 108300 | AA697: 104900 | AB697: 104900 | AC697: 103200 | AD697: 102300
A698: MYB | B698: 7098310224_ID-13971330236 | C698: =_xlfn.NUMBERVALUE(LEFT(B698,10)) | D698: =_xlfn.NUMBERVALUE(RIGHT(B698,11)) | E698: 6902395834410 | F698: Maybelline Fit Me Matte + Poreless Liquid Foundation Make Up 30ml - Makeup Ringan Full Coverage 16HR Oil Control | J698: 171900 | K698: 0.32 | L698: 0.33 | M698: 0.37 | N698: 0.365 | O698: 0.37 | P698: 0.39 | Q698: 0.39 | R698: 0.4 | S698: 0.405 | V698: 116900 | W698: 115200 | X698: 108300 | Y698: 109200 | Z698: 108300 | AA698: 104900 | AB698: 104900 | AC698: 103200 | AD698: 102300
A699: MYB | B699: 7098310224_ID-13971334240 | C699: =_xlfn.NUMBERVALUE(LEFT(B699,10)) | D699: =_xlfn.NUMBERVALUE(RIGHT(B699,11)) | E699: 6902395774433 | F699: Maybelline Fit Me Matte + Poreless Liquid Foundation Make Up 30ml - Makeup Ringan Full Coverage 16HR Oil Control | J699: 171900 | K699: 0.32 | L699: 0.33 | M699: 0.37 | N699: 0.365 | O699: 0.37 | P699: 0.39 | Q699: 0.39 | R699: 0.4 | S699: 0.405 | V699: 116900 | W699: 115200 | X699: 108300 | Y699: 109200 | Z699: 108300 | AA699: 104900 | AB699: 104900 | AC699: 103200 | AD699: 102300
A700: MYB | B700: 7098310224_ID-13971334241 | C700: =_xlfn.NUMBERVALUE(LEFT(B700,10)) | D700: =_xlfn.NUMBERVALUE(RIGHT(B700,11)) | E700: 6902395826934 | F700: Maybelline Fit Me Matte + Poreless Liquid Foundation Make Up 30ml - Makeup Ringan Full Coverage 16HR Oil Control | J700: 171900 | K700: 0.32 | L700: 0.33 | M700: 0.37 | N700: 0.365 | O700: 0.37 | P700: 0.39 | Q700: 0.39 | R700: 0.4 | S700: 0.405 | V700: 116900 | W700: 115200 | X700: 108300 | Y700: 109200 | Z700: 108300 | AA700: 104900 | AB700: 104900 | AC700: 103200 | AD700: 102300
A701: MYB | B701: 7098310224_ID-13971334249 | C701: =_xlfn.NUMBERVALUE(LEFT(B701,10)) | D701: =_xlfn.NUMBERVALUE(RIGHT(B701,11)) | E701: 6902395826941 | F701: Maybelline Fit Me Matte + Poreless Liquid Foundation Make Up 30ml - Makeup Ringan Full Coverage 16HR Oil Control | J701: 171900 | K701: 0.32 | L701: 0.33 | M701: 0.37 | N701: 0.365 | O701: 0.37 | P701: 0.39 | Q701: 0.39 | R701: 0.4 | S701: 0.405 | V701: 116900 | W701: 115200 | X701: 108300 | Y701: 109200 | Z701: 108300 | AA701: 104900 | AB701: 104900 | AC701: 103200 | AD701: 102300
A702: MYB | B702: 7098310224_ID-13971358053 | C702: =_xlfn.NUMBERVALUE(LEFT(B702,10)) | D702: =_xlfn.NUMBERVALUE(RIGHT(B702,11)) | E702: 6902395774426 | F702: Maybelline Fit Me Matte + Poreless Liquid Foundation Make Up 30ml - Makeup Ringan Full Coverage 16HR Oil Control | J702: 171900 | K702: 0.32 | L702: 0.33 | M702: 0.37 | N702: 0.365 | O702: 0.37 | P702: 0.39 | Q702: 0.39 | R702: 0.4 | S702: 0.405 | V702: 116900 | W702: 115200 | X702: 108300 | Y702: 109200 | Z702: 108300 | AA702: 104900 | AB702: 104900 | AC702: 103200 | AD702: 102300
A703: MYB | B703: 7488896493_ID-13903000882 | C703: =_xlfn.NUMBERVALUE(LEFT(B703,10)) | D703: =_xlfn.NUMBERVALUE(RIGHT(B703,11)) | E703: 6902395843467 | F703: Maybelline Lip & Eye Makeup Remover - 150 ml Mudah Hapus Make Up Waterproof | J703: 145900 | K703: 0.2 | L703: 0.21 | M703: 0.22 | N703: 0.22 | O703: 0.25 | P703: 0.27 | Q703: 0.27 | R703: 0.28 | S703: 0.29 | V703: 116800 | W703: 115300 | X703: 113900 | Y703: 113900 | Z703: 109500 | AA703: 106600 | AB703: 106600 | AC703: 105100 | AD703: 103600
A704: MYB | B704: 7488888545_ID-13902992712 | C704: =_xlfn.NUMBERVALUE(LEFT(B704,10)) | D704: =_xlfn.NUMBERVALUE(RIGHT(B704,11)) | E704: 6902395847335 | F704: Maybelline Lip & Eye Makeup Remover - 70 ml Pembersih Wajah Mudah Hapus Make Up Waterproof | J704: 95900 | K704: 0.2 | L704: 0.21 | M704: 0.22 | N704: 0.22 | O704: 0.25 | P704: 0.27 | Q704: 0.27 | R704: 0.28 | S704: 0.29 | V704: 76800 | W704: 75800 | X704: 74900 | Y704: 74900 | Z704: 72000 | AA704: 70100 | AB704: 70100 | AC704: 69100 | AD704: 68100
A705: MYB | B705: 7474598120_ID-13887174045 | C705: =_xlfn.NUMBERVALUE(LEFT(B705,10)) | D705: =_xlfn.NUMBERVALUE(RIGHT(B705,11)) | E705: 6902395844914 | F705: Maybelline Tattoo Liner 48H Liquid Pen Eyeliner Waterproof Makeup (Tahan Lama Hingga 48 Jam, Smudgeproof, Hitam Intens, Liquid Eyeliner) | J705: 93900 | K705: 0.28 | L705: 0.285 | M705: 0.295 | N705: 0.29 | O705: 0.3 | P705: 0.31 | Q705: 0.3 | R705: 0.31 | S705: 0.32 | V705: 67700 | W705: 67200 | X705: 66200 | Y705: 66700 | Z705: 65800 | AA705: 64800 | AB705: 65800 | AC705: 64800 | AD705: 63900
...

Sheet Data_Validations
A1: Archetype | B1: E-Boutique | D1: Market 1 | E1: Australia / New Zealand | G1: Country 1 | H1: Malaysia | K1: Division | L1: Consumer Products Division (CPD) | N1: Brands | O1: Not Applicable | Q1: Request type | R1: Not Applicable | T1: Request SubType | U1: Not Applicable | W1: Platform | X1: Not Applicable | Z1: Date | AA1: =TODAY()
B2: E-Retailers | E2: India | H2: Singapore | L2: L’Oréal Dermatological Beauty (LDB) | O2: Biotherm | R2: Campaign Management | U2: New Product Listing | X2: Lazada
B3: Marketplace | E3: Indonesia | L3: L’Oréal Luxe Division (LLD) | O3: CeraVe | R3: Copywriting | U3: Product Details Update | X3: Shopee
B4: Pureplayers | E4: Malaysia / Singapore | L4: Professional Products Division (PPD) | O4: Garnier | R4: Product Management | U4: Price Update (Bulk,TB,BMO, CBMO) | X4: Tokopedia
E5: Thailand | G5: Country 2 | H5: Australia | O5: Kérastase | U5: Promo Mechanic Creation
H6: New Zealand | O6: Kiehl's | U6: Asset Creation
O7: La Roche Posay | U7: Copywriting
O8: Lancôme | U8: Others
D9: Market 2 | E9: Australia / New Zealand | G9: Country 3 | H9: India | O9: L'Oréal Paris
E10: India | O10: L'Oréal Professionnel
E11: Malaysia / Singapore | G11: Country 4 | H11: Thailand | O11: Maybelline
O12: Shu Uemura
D13: Market 3 | E13: Australia / New Zealand | G13: Country 5 | H13: Vietnam | O13: Vichy
E14: India
E15: Malaysia / Singapore | G15: Country 6 | H15: Indonesia
D17: Market 4 | E17: India

Sheet Instruction
M2: Click here to access the guide (ACN)
B6: Template Name | D6: Loreal Campaign Brief Template
B7: Purpose | D7: This template is mandatory to request Content Listing/Updation and Campaign management on Marketplace
B8: Business User | D8: The Online Brand Manager (OBM) & Brand Platform Manager (BPM) is typically responsible for submitting the template
B9: Information security | D9: The template may include restricted data for pre-launch products
B10: Need Help? | D10: Confirmation needed if any support team email ID can be addedd
B12: Type of Input require | D12: Fixed | I12: Template applicable as per request
D13: *Mandatory | I13: Request type | J13: Applicable Template
D14: Optional | I14: Mega Campaign - Price Change (TB)-LZD | J14: Mega Campaign - Price Change (TB)-LZD
D15: Dropdown | I15: Promotion Mechanics -Flexi Combo-LZD | J15: Promo-Flexi Combo-LZD
I16: Promotion Mechanics - Voucher-LZD | J16: Promo-Voucher-LZD
B17: How to use the Template | I17: Promotion Mechanics -Brand Membership-LZD | J17: Promo-Brand Membership-LZD
B18: Overview | D18: Please refer Overview tab and provide all the mandatory attributes marked as * | I18: CEM-LZD | J18: CEM-LZD
D19: Select the Market, Country, Division, Brand, Archetype and Platform | I19: Visual Brief Requirements from Loreal-LZD | J19: Visual Brief Req.-LZD
D20: Please input Request Name as per the | I20: Visual A revised-LZD | J20: Visual A revised-LZD
I21: Wireframe Revised-LZD | J21: Wireframe Revised-LZD
I22: Wireframe LZD SBD MCP SIS | J22: Wireframe LZD SBD MCP SIS
I23: Launch Requirement (FG)-LZD | J23: Launch Requirement (FG)-LZD
B24: How to use the Template | I24: Launch Req. (GWP, Sample)-LZD | J24: Launch Req. (GWP, Sample)-LZD
B25: 1 | C25: Overview | D25: Go to Overview tab - Provide information for all the mandatory attributes marked as "*". Select the Market, Country, Division, Brand, Platform, Request Type, Prioritization using the dropdown.
B29: 2 | C29: Price Change | D29: Please provide any additional information using the applicable tabs. e.g. Price: For any price change request including Treasure Bowl submission Promo: For any promo setup require e.g. Voucher creation, Free Shipping setup, etc. VB: Virtual Bundle setup Visual A/Visual B: For any visual request - can use both or either one Launch Requirement: New Product listing
I30: What is request type? | J30: Request type will define the task needed to be actioned
I31: New Product Listing | J31: Listing of new product information/content on sales platform
I32: Product Update | J32: Changes needed in the existing PDP content
B33: 3 | C33: Help Needed | D33: To access the applicable teamplate refer to "Template applicable as per request" in Overview tab | I33: Mega Campaign | J33: Campaign specifically targeting on an upcoming event
I34: BAU Campaign | J34: General campaign
I35: Adhoc campaign | J35: Additional campaign
B36: 4 | C36: How to share the template? | D36: Attach the completed template in SynOps Ticket | F36: SynOps link (Can we add CXL link) | I36: CPAS | J36: Collaborative Performance Advertising Solutions (CPAS), rebranded as Collaborative Ads, are an advertising solution created by Facebook (now Meta) allowing brands and retailers to create ads together.
I39: What is Prioritisation | J39: It defines the urgency of the task/request
I40: BAU | J40: Defined SLA for each task
I41: Priority | J41: Requests which will be completed within 24 hours
I42: Super Priority | J42: Requests with minimum number of changes to be completed in few hour(1-4 hours) | L42: SLA DETAILS | M42: To include details in table once finalised
M43: Synops SLAs (UAT)

Sheet Overview
A2: Type of Input require | B2: Fixed
B3: Optional
B4: Dropdown
A7: REQUEST TYPE* | D7: Select Request Type
A8: CAMPAIGN NAME* | D8: Select Campaign Name
A9: SUBCAMPAIGN NAME | D9: Select Subcampaign Name
A10: MARKET LEVEL CAMPAIGN NAME*
A11: PRIORITISATION* | D11: Select Priority
A14: Thailand (TH)
A15: PROMOTION TYPE & DATE: | D15: PLATFORM e.g. Shopee | E15: PROMOTION TYPE e.g. Teasing | G15: START DATE e.g. 1-Sep-22 | H15: END DATE e.g. 8-Sep-22 | I15: REMARKS | K15: 4.4 Raya (D-Day)
D16: Select Platforms | E16: Derma Campaign | G16: 45220 | H16: 45221 | K16: CPAS - 22-Mar go live, Publicis receive brief 6-Mar, visual 3-4 working days (16-mar, actual)
D17: Select Platforms | K17: SIS -
D18: Select Platforms | K18: PDP (Hero) - 22-Mar go live
D19: Select Platforms | K19: MMT need 24-48 hrs to upload
D20: Select Platforms | K20: Promo plan: 20 Feb 80%
A21: SELLER CENTRE SETUP e.g. MECHANICS & USP FOR VISUALS | D21: SC SETUP / MECHANICS TYPE | E21: LAZADA
E22: PPROMO (Y/N) | F22: VISUAL KEY MESSAGING | G22: REMARKS
C23: 1 | D23: Price Change - TB | E23: Yes
C24: 2 | D24: Price Change - TB - FS | E24: Yes
C25: 3 | D25: Price Change - SIS - FS | E25: No
C26: 4 | D26: Promotion - Flexi Combo | E26: Yes
C27: 5 | D27: Promotion - Voucher | E27: Yes
C28: 6 | D28: Promotion - Brand Membership | E28: No
C29: 7 | D29: CEM | E29: No
C30: 8 | D30: Feed | E30: No
C31: 9 | D31: Visual Brief | E31: No
C32: 10 | D32: Visibility Brief | E32: No
C33: 11 | D33: Wireframe | E33: No
C34: 12 | D34: New Product Listing (NPD) | E34: No
... C36: 14 | D36: Virtual Bundle (VB) Listing | E36: No
A38: SINGAPORE (SG)
A39: PROMOTION TYPE & DATE: | D39: PLATFORM e.g. Shopee | E39: PROMOTION TYPE e.g. Teasing | G39: START DATE e.g. 1-Sep-22 | H39: END DATE e.g. 8-Sep-22 | I39: REMARKS
D40: Select Platforms
D41: Select Platforms
D42: Select Platforms
D43: Select Platforms
D44: Select Platforms
A45: SELLER CENTRE SETUP e.g. MECHANICS & USP FOR VISUALS | D45: SC SETUP / MECHANICS TYPE | E45: LAZADA | H45: SHOPEE
E46: PPROMO (Y/N) | F46: VISUAL KEY MESSAGING | G46: REMARKS | H46: PPROMO (Y/N) | I46: VISUAL KEY MESSAGING | J46: REMARKS
C47: 1 | D47: PRICE CHANGE - Promo, Flash, etc. | E47: Yes | H47: Select from Dropdown
...

Sheet Brief Guide
A1: No | B1: Tab Name | C1: Details | D1: Output
A2: 1 | B2: Instruction | C2: Instruction/guide for L'Oreal on how to fill-up brief template | D2: Input Accuracy
A3: 2 | B3: Overview | C3: To capture important fields for the request: 1) Market 2) Country 3) Division 4) Brand 5) Archetype 6) Platform 7) Request Name 8) Theme 9) Asstes Link 10) Elements 11) Promotion Type & Date 12) Mechanics & USP for Visual 13) Assets Deliverables | D3: - Request details: Market, Country, Division, Brand, Archetype, Platform, Request Name, Theme, Asstes Link - Delivery date, Go-Live date - Mechanics for Seller Centre Setup - Type of assets
A4: 3 | B4: Promo | C4: Mechanics for Seller Centre Setup | D4: Creation below mechanic on Seller Centre - Voucher - Free Shipping - Flexi Combo - Brand Membership
A5: 4 | B5: Virtual Bundle (VB) | C5: Virtual Bundle details for Seller Centre Setup | D5: Creation of Virtual Bundle on Seller Centre
A6: 5 | B6: Price | C6: Price change/submission | D6: Price change/submission on Seller Centre
A7: 6 | B7: Visual A | C7: Submission of visual request and copywriting on assets if require | D7: Type of assets and its content
A8: 7 | B8: Visual B | C8: Visual request and copywriting (if require) - copy paste wireframe | D8: Type of assets and its content

Sheet Price Change (SIS-FS) -LZD
B1: Type of Input require | C1: *Mandatory Fields | E1: Changes done as per feedback | I1: Key Notes
C2: Optional Fields | I2: 1. Kindly duplicate the table for additional campaigns that you may want to add for any month
C3: Dropdown
B4: *Please take note for any input with double pricing with same date/duration, SVC will submit the lowest price
B6: Promotion Type: Mega Day (applicable for campaign with no specific timing) | J6: Promotion Type: BAU only (applicable for campaign with no specific timing) | R6: Promotion Type: Flash etc (applicable for campaign with specific timing) | AA6: Promotion Type: Flash, BMO, etc (applicable for campaign with specific timing)
B7: Campaign Name* | D7: Name of the campaign | J7: Campaign Name* | L7: Name of the campaign | R7: Campaign Name* | T7: Name of the campaign | AA7: Campaign Name* | AC7: Name of the campaign
B8: Start Date* | C8: Start Date | F8: Start Time* | G8: Start Time | J8: Start Date* | K8: Start Date | N8: Start Time* | O8: Start Time | R8: Start Date* | S8: Start Date | V8: Start Time* | W8: Start Time | AA8: Start Date* | AB8: Start Date | AE8: Start Time* | AF8: Start Time
B9: End Date* | C9: End Date | F9: End Time* | G9: End Time | J9: End Date* | K9: End Date | N9: End Time* | O9: End Time | R9: End Date* | S9: End Date | V9: End Time* | W9: End Time | AA9: End Date* | AB9: End Date | AE9: End Time* | AF9: End Time
B10: Platform* | C10: Lazada SKU* | D10: EAN* | E10: Product Name | F10: Current Price - RSP (THB) | G10: Discount (%) (Optional - for validation) | H10: Price (Campaign Price)* | I10: Remarks | J10: Platform* | K10: Lazada SKU* | L10: EAN* | M10: Product Name | N10: Current Price - RSP (THB) | O10: Discount (%) (Optional - for validation) | P10: Price (Campaign Price)* | Q10: Remarks | R10: Platform* | S10: Lazada SKU* | T10: EAN* | U10: Product Name | V10: Current Price - RSP (THB) | W10: Discount (%) (Optional - for validation) | X10: Rebate (for CPD division) | Y10: Offer Price (Campaign Price)* | Z10: Remarks | AA10: Platform* | AB10: Lazada SKU* | AC10: EAN* | AD10: Product Name | AE10: Current Price - RSP (THB) | AF10: Discount (%) (Optional - for validation) | AG10: Price (Campaign Price)* | AH10: Remarks
A11: Example | B11: Lazada | C11: 830914469_TH-1974242308 | D11: 6902395827375 | E11: Maybelline City Mini Palette Eyeshadow - Uncaged Limited Edition | H11: 99.00 | J11: Lazada | K11: 830914469_TH-1974242308 | L11: 6902395827375 | M11: Maybelline City Mini Palette Eyeshadow - Uncaged Limited Edition | P11: 99.00 | R11: Lazada | S11: 830914469_TH-1974242308 | T11: 6902395827375 | U11: Maybelline City Mini Palette Eyeshadow - Uncaged Limited Edition | Y11: 99.00 | AA11: Lazada | AB11: 830914469_TH-1974242308 | AC11: 6902395827375 | AD11: Maybelline City Mini Palette Eyeshadow - Uncaged Limited Edition | AG11: 99.00

Sheet Dropdown list
A1: Campaign Type | B1: Platform | C1: Campaign Tiering | D1: Voucher Type | E1: Brand Membership - Discount Type | F1: Voucher - Discount Type | G1: Type of Members | H1: Member Group | I1: Type of Mechanics | J1: Type of Add-on Promotion | K1: NA | L1: GWP - FlexiComboMechanics | M1: StorewidevsSpecific | N1: MoneyorDiscount | O1: Main Product or GWP | P1: Product Type | Q1: Combobuy | R1: FixedPrice | S1: DealCriteria | T1: SIS Time slot | U1: Stackable/ Unstackable | V1: VBOM/Single/Bundle | W1: Platform | X1: Ad Type | Y1: Concate - Ad Type | Z1: Banner Placement | AA1: Platform | AB1: Ad Type | AC1: Concate - Ad Type | AD1: Banner Placement | AF1: Banner Placement | AG1: Banner Size | AH1: Service Center | AK1: CEM-Pool Choice | AL1: CEM-Target Audience
A2: Select Campaign Type | B2: Select Platform | C2: Select from below Campaign | D2: Select from Dropdown | E2: Select Discount Type | F2: Select Discount Type | G2: Select type of Member | H2: Select from Dropdown | I2: Select from Dropdown | J2: Select from Dropdown | K2: Select from Dropdown | L2: Select from Dropdown | M2: Select from Dropdown | N2: Select from Dropdown | O2: Select from Dropdown | P2: Select from Dropdown | Q2: Select from Dropdown | R2: Select from Dropdown | S2: Select from Dropdown | T2: Select from Dropdown | U2: Select from Dropdown | V2: Select from Dropdown | W2: Lazada | X2: Off-Platform | Y2: LazadaOff-Platform | Z2: FB Post (Collection Ads) | AA2: Shoppe | AB2: Off-Platform | AC2: ShopeeOff-Platform | AD2: FB Post | AE2: Lazada | AF2: FB Post (Collection Ads) | AG2: 1000 x 1000 | AH2: Select Status | AK2: Select Input | AL2: Select Input
A3: Mega | B3: Shopee | C3: SBD | D3: LZD - Store Follower | E3: Voucher - Percentage | F3: Percentage | G3: Welcome | H3: Silver and above | I3: LZD -Welcome Vouhcer | J3: Price | K3: NA | L3: Percentage | M3: Store-wide | N3: Money Value Off | O3: Main | P3: FG | Q3: Percentage Discount Off & Free Gift(s) | R3: NA | S3: Any Item Quantity + Order Value Reaches X | T3: 00:00 - 08:00 | U3: Yes | V3: Single | X3: On-Platform | Y3: LazadaOn-Platform | Z3: IG Story | AB3: On-Platform | AC3: ShopeeOn-Platform | AD3: IG Story | AF3: IG Story | AG3: 1080 x 1920 | AH3: Awaiting Confirmation | AK3: Remind Cart Item | AL3: All Follower
A4: Medium | B4: Lazada | C4: Mega (Double day) | D4: LZD - Regular | E4: Voucher - Fixed Price | F4: Fixed Price | G4: Regular | H4: Gold and above | I4: LZD - Linked Member Voucher | J4: Discount off | L4: Money Off | M4: Specific SKUs | N4: Percentage Discount Off | O4: GWP | P4: Sample | Q4: Money Value Off & Free Gift(s) | S4: Order Value Reaches X | T4: 08:00 - 12:00 | U4: No | V4: Physical Bundle | Z4: Affliate - LZ | AD4: Affliate - SH | AF4: Affliate - LZ | AG4: 1200 x 628, 120 x 600, 320 x 50, 300 x 250, 600 x 600 | AH4: Pending | AK4: Share New Arrival | AL4: Brand Membership
A5: Small | C5: Payday | D5: LZD - New Buyer | E5: CCB - Percentage | H5: Platinum and above | I5: LZD - Welcome Product Offer | L5: Free gift/sample | P5: Other | Q5: Percentage Discount Off & Free Sample(s) | S5: Item Quantity Reaches X | T5: 12:00 - 18:00 | V5: Virtual Bundle | Z5: FEED | AD5: FEED | AF5: FEED | AG5: 600 x 600 (Perfect square) | AH5: On Hold | AK5: Offer Voucher | AL5: Shop Follower
C6: Category Campaign | D6: LZD - Live Stream | E6: CCB - Fixed Price | H6: Diamond Only | I6: LZD - Linked Member Product Offer | L6: Combo buy (Percentage and gift) | Q6: Money Value Off & Free Sample(s) | S6: Any Item Quantity Reaches X | T6: 18:00 - 20:00 | Z6: Carousel Banner (Shop-in-Shop) | AD6: Video | AF6: Carousel Banner (Shop-in-Shop) | AG6: 1200 x 568 | AH6: Completed | AK6: Inform Promotion
C7: BAU | D7: LZD - Others (Unique voucher) | E7: Member Price - Percentage | H7: All Members | I7: LZD - New Member Voucher | L7: Combo buy (Fixed price and gift) | S7: Buy Any X, Get Any GWP | T7: 20:00 - 22:00 | Z7: Top Banner (Shop-in-Shop) | AD7: Carousel | AF7: Top Banner (Shop-in-Shop) | AG7: 1200 x 600 | AH7: Cancelled | AK7: Custom Message
D8: LZD - Co-Funded Voucher | E8: Gift | I8: LZD - Member-exclusive Voucher | T8: 22:00 - 24:00 | Z8: Middle Banner (Shop-in-Shop) | AD8: Multiple Images | AF8: Middle Banner (Shop-in-Shop) | AG8: 1200 x 353
D9: SHP - Shop Voucher | E9: Points Multiplier | I9: LZD - Points Redeemable Voucher | Z9: Bottom Banner (Shop-in-Shop) | AD9: Banner and Category | AF9: Bottom Banner (Shop-in-Shop) | AG9: 1200 x 600
D10: SHP - Product Voucher | E10: Sign on Bonus | I10: LZD - New Member Product Offer | Z10: Followers Banner (Shop-in-Shop) | AD10: Single Image | AF10: Followers Banner (Shop-in-Shop) | AG10: 1200 x 288
D11: SHP - Private Voucher | E11: Member Exclusive Price | I11: LZD - Member Product Offer | L11: Money (tiering) /Discount % | M11: MoneyorDiscount | Z11: Category Banner (Shop-in-Shop) | AD11: Multiple Clickable Ares | AF11: Category Banner (Shop-in-Shop) | AG11: 1200 x 150
D12: SHP - Live Voucher | I12: LZD - Points Redeemable Product | L12: Free gift/sample | M12: Freegiftorsample | Z12: Homepage Banner 1 | AD12: Image Category List | AF12: Homepage Banner 1 | AG12: 796 x 235
D13: SHP - Video Voucher | I13: SHP - Welcome Voucher | L13: Combo buy (discount and free gift) | M13: Combobuy | Z13: Homepage Banner 2 | AD13: Homepage Banner 1 | AF13: Homepage Banner 2 | AG13: 398 x 115
D14: SHP - New Buyer Voucher | I14: SHP - Welcome Gift | L14: Fixed price | M14: FixedPrice | Z14: Homepage Banner 3 | AD14: Homepage Banner 2 | AF14: Homepage Banner 3 | AG14: 398 x 115
D15: SHP - Repeat Buyer Voucher | I15: SHP - Sign-on Points Multiplier | Z15: Lazada Mall (Homepage Banner) | AD15: Homepage Banner 3 | AF15: Lazada Mall (Homepage Banner) | AG15: 390 x 463
D16: SHP - Follow Prize Voucher | I16: SHP - Exclusive Voucher | Z16: Shopee Mall (Homepage Banner) | AD16: Shopee Mall (Homepage Banner) | AF16: Shopee Mall (Homepage Banner) | AG16: 1200 x 600, 1200 x 969
D17: SHP - Exclusive Streamer Voucher | I17: SHP - Member Repeat Buyer | Z17: Lazada Category Banner | AD17: Shopee Mall (Homepage Banner) | AF17: Lazada Category Banner | AG17: 1360 x 480
I18: SHP - Member Exclusive Price | Z18: Livestream Banner | AD18: Shopee Groceries Category Banner (Category Homepage) | AF18: Livestream Banner | AG18: 500 x 500
I19: SHP - Gift Redemption | AD19: Livestream Banner | AF19: FB Post | AG19: 1000 x 1000
I20: SHP - Voucher Redemption | AF20: Affliate - SH | AG20: 1080 x 1080, 1080 x 1920, 160 x 600, 210 x 600, 250 x 300 , 300 x 250, 300 x 50, 320 x 50, 320 x 480, 728 x 90
I21: SHP - Points Multiplier Campaign | AF21: FEED | AG21: Perfect square 600 x 600 (Content similar to SIS Main Banner)
I22: SHP - Member Exclusive Product | AF22: Video | AG22: Max Width 1280px Max Height 1280px
AF23: Carousel | AG23: Max Width 2000px Max Height 2000px
AF24: Multiple Images | AG24: Max Width 2000px Max Height 2000px
A25: Hero/Non Hero | B25: Market | C25: Yes/No | D25: Division | E25: Single/VBOM/Bundle | G25: BRAND | H25: Dropdown | I25: Subsidy | J25: Request Type | K25: PRIORITISATION | L25: Main/Subproduct | M25: CPD | N25: PPD | P25: LLD | Q25: LDB | AF25: Banner and Category | AG25: Max Width 1200px Max Height 100px - 900px
A26: Hero | B26: Select Market | C26: Select from Dropdown | D26: Select Division | E26: Single | G26: Select Brand | H26: Select Promo Type | I26: Select from Dropdown | J26: Select Request Type | K26: Select Priority | L26: Select Product type | M26: OAP | N26: LORP | P26: LAN | Q26: LRP | AF26: Single Image | AG26: Max Width 1200px Max Height 100px - 2200px
A27: Non-Hero | B27: Thailand | C27: Yes | D27: CPD | E27: VBOM | G27: Garnier | H27: PROMO | I27: Partial | J27: New product Listing | K27: BAU | L27: Main Product | M27: MNY | N27: KER | P27: BIO | Q27: VIC | AF27: Multiple Clickable Ares | AG27: Max Width 1200px Max Height 100px - 2200px
C28: No | D28: PPD | E28: Bundle | G28: L'Oreal Paris | H28: FLASH | I28: Full | J28: Product Update | K28: Priority | L28: Sub-Product | M28: GAR | P28: SHU | Q28: CRV | AF28: Image Category List | AG28: Max Width 300px Max Height 300px
D29: LDB | G29: Maybelline | H29: CBMO | J29: Mega Campaign | K29: Super Priority | P29: KIE | Q29: SKC | AF29: Shopee Mall (Homepage Banner) | AG29: 390 x 463
D30: LLD | G30: 3CE | H30: BMO | J30: BAU Campaign | P30: ITC | AF30: Shopee Mall (Homepage Banner) | AG30: 1200 x 600 1200 x 969
G31: Lancome | H31: Others | J31: Adhoc Campaign | AF31: Shopee Groceries Category Banner (Category Homepage) | AG31: 1200 x 360
G32: Shu Uemura | J32: CPAS
G33: Kiehl's
G34: Biotherm
G35: It Cosmetics
G36: L'Oreal Professional
G37: Kerastase
G38: La Roche Posay
G39: Cerave
G40: Skinceuticals
...

Sheet Data Quality Checklist
B2: Sheet | C2: Column | D2: Column Letter | E2: Rule | F2: Message | G2: Formula | H2: Error Check Type
B3: Campaign Calendar | C3: Start Date | D3: E | E3: DQ Rule # 3 : Start Date & End Date should follow dd-mmm-yyyy | F3: Formating Error. Please re-format as dd-mmm-yyyy e.g 01-Dec-2024 | G3: ISNUMBER(DATEVALUE(TEXT(A1,"dd-mmm-yy"))) | H3: Data Validation - Format
B4: Campaign Calendar | C4: End Date | D4: F | E4: DQ Rule # 3 : Start Date & End Date should follow dd-mmm-yyyy | F4: Formating Error. Please re-format as dd-mmm-yyyy e.g 01-Dec-2024 | G4: ISNUMBER(DATEVALUE(TEXT(A1,"dd-mmm-yy"))) | H4: Data Validation - Format
B5: Campaign Calendar | C5: Start Time | D5: G | E5: DQ Rule # 6 : Start Time & End Time should be formatted as h:mm. | F5: Formating Error. Please re-format as hh : mm AM / PM e.g 12 : 00 AM | G5: AND(ISNUMBER(TIMEVALUE(TEXT(A1,"hh:mm AM/PM"))),HOUR(A1)>=0,HOUR(A1)<24) | H5: Data Validation - Format
B6: Campaign Calendar | C6: End Time | D6: H | E6: DQ Rule # 6 : Start Time & End Time should be formatted as h:mm. | F6: Formating Error. Please re-format as hh : mm AM / PM e.g 12 : 00 AM | G6: AND(ISNUMBER(TIMEVALUE(TEXT(A1,"hh:mm AM/PM"))),HOUR(A1)>=0,HOUR(A1)<24) | H6: Data Validation - Format
B7: Campaign Calendar | C7: Campaign Type | D7: J | E7: DQ Rule # 7 : Campaign Type should follow defined categorical values. | F7: Please select from drop-down menu. To add more options, go to the Dropdown list tab and add the new option under Campaign Type | G7: NA | H7: Data Validation - List
B8: Campaign Calendar | C8: Campaign Tiering | D8: K | E8: DQ Rule # 7 : Campaign Type should follow defined categorical values. | F8: Please select from drop-down menu. To add more options, go to the Dropdown list tab and add the new option under Campaign Tiering | G8: NA | H8: Data Validation - List
B9: Price Change | C9: EAN Code | D9: B | E9: DQ Rule # 10 : EAN Code should only contain digits (0-9), not alphabets or special characters. | F9: EAN, Product and Variation code MUST only contain digits (0-9), non alphabets or special characters | G9: NA | H9: Data Validation - Whole Number
B10: Price Change | C10: EAN Code | D10: B | E10: DQ Rule # 11 : There should only be 1 row per EAN code (i.e. EAN codes should not be repeated/duplicated) | F10: Red Highlight | G10: NA | H10: Conditional Formatting - Duplication
B11: Price Change | C11: Variation ID | D11: E | E11: DQ Rule # 11 : There should only be 1 row per EAN code (i.e. EAN codes should not be repeated/duplicated) | F11: Red Highlight | G11: NA | H11: Conditional Formatting - Duplication
B12: Price Change | C12: Product ID | D12: D | E12: DQ Rule # 12 : Product ID & Variation ID should only contain digits (0-9), no alphabets or special characters. | F12: EAN, Product and Variation code MUST only contain digits (0-9), non alphabets or special characters | G12: NA | H12: Data Validation - Whole Number
B13: Price Change | C13: Variation ID | D13: E | E13: DQ Rule # 12 : Product ID & Variation ID should only contain digits (0-9), no alphabets or special characters. | F13: EAN, Product and Variation code MUST only contain digits (0-9), non alphabets or special characters | G13: NA | H13: Data Validation - Whole Number
... B16: Price Change | C16: Promo Discount % | D16: S | E16: DQ Rule 18 : Promo Discount % should be: 0 <= Promo Discount % < 1 | F16: Price Discount must be within 0 % to 70%. Please validate the L'Oreal Recommended Price, Discount or Campaign Price | G16: AND(A1>=0, A1<0.7) | H16: Data Validation - Custom

Sheet Campaign Calendar
C1: Type of Input require | D1: *Mandatory Fields | M1: SVC Use Only >>> Status of Data Entry
D2: Optional Fields | M2: Awaiting Confirmation | N2: =COUNTIF($L11:$L53, M2) / COUNTIF($J11:$J53,"<>")
D3: Dropdown | M3: Pending | N3: =COUNTIF($L11:$L53, M3) / COUNTIF($J11:$J53,"<>")
M4: On Hold | N4: =COUNTIF($L11:$L53, M4) / COUNTIF($J11:$J53,"<>")
M5: Completed | N5: =COUNTIF($L11:$L53, M5) / COUNTIF($J11:$J53,"<>")
M6: Cancelled | N6: =COUNTIF($L11:$L53, M6) / COUNTIF($J11:$J53,"<>")
D7: Dropdown | E7: DQ - Format | F7: DQ - Format | G7: DQ - Format | H7: DQ - Format | I7: DQ - Duplicate
C8: PLEASE INPUT ALL MANDATORY FIELDS FOR DROP-DOWN & AUTOFILLS
C9: Select from drop-down menu | D9: Enter full brand name | E9: Enter Start Date as dd-MMM-yyyy e.g 03-Apr-2024 | F9: Enter End Date as dd-MMM-yyyy e.g 03-Apr-2024 | G9: Enter Start time as hh:mm:ss e.g 23:59:59 | H9: Enter End time as hh:mm:ss e.g 23:59:59 | I9: Enter Unique Campaign Name. Must not be duplicated to avoid errors in price change. E.g Payday 25 Apr, Payday 26-31 Apr | J9: Enter Generic Campaign Type Name E.g Double Date, Teasing, Payday | K9: Enter Tiers that will be applied for the campaign. E.g "MG", "T1, 2.5 , T3 + 5.-", "10%" | L9: For Service center use only.
C10: Platform | D10: Brand | E10: Start Date | F10: End Date | G10: Start Time | H10: End Time | I10: Campaign Name | J10: Campaign Type | K10: Campaign Tiering | L10: Price Change Status
C11: Lazada | D11: Loreal Paris | E11: 46082 | F11: 46112 | G11: 0 | H11: 0.99930556 | I11: BAU Full Day | J11: BAU
C12: Lazada | D12: Loreal Paris | E12: 46082 | F12: 46112 | G12: 0 | H12: 0.99930556 | I12: BAU Laz Flash | J12: BAU
C13: Lazada | D13: Loreal Paris | E13: 46082 | F13: 46112 | G13: 0 | H13: 0.99930556 | I13: Mar Membership | J13: Members
C14: Lazada | D14: Loreal Paris | E14: 46083 | F14: 46086 | G14: 0.83333333 | H14: 0.99930556 | I14: 3.3 Sale x Raya Full Day | J14: Double Digit (Mega)
C15: Lazada | D15: Loreal Paris | E15: 46083 | F15: 46086 | G15: 0.83333333 | H15: 0.99930556 | I15: 3.3 Sale x Raya CBMO | J15: Double Digit (Mega)
C16: Lazada | D16: Loreal Paris | E16: 46083 | F16: 46086 | G16: 0.83333333 | H16: 0.99930556 | I16: 3.3 Sale x Raya Laz Flash | J16: Double Digit (Mega)
C17: Lazada | D17: Loreal Paris | E17: 46095 | F17: 46098 | G17: 0.83333333 | H17: 0.99930556 | I17: MMS x Raya Full Day | J17: MMS
C18: Lazada | D18: Loreal Paris | E18: 46095 | F18: 46098 | G18: 0.83333333 | H18: 0.99930556 | I18: MMS x Raya CMBO | J18: MMS
C19: Lazada | D19: Loreal Paris | E19: 46095 | F19: 46098 | G19: 0.83333333 | H19: 0.99930556 | I19: MMS x Raya Laz Flash | J19: MMS
C20: Lazada | D20: Loreal Paris | E20: 46105 | F20: 46108 | G20: 0.83333333 | H20: 0.99930556 | I20: PDS x Birthday Full Day | J20: PDS (Mega)
C21: Lazada | D21: Loreal Paris | E21: 46105 | F21: 46108 | G21: 0.83333333 | H21: 0.99930556 | I21: PDS x Birthday CMBO | J21: PDS (Mega)
C22: Lazada | D22: Loreal Paris | E22: 46105 | F22: 46108 | G22: 0.83333333 | H22: 0.99930556 | I22: PDS x Birthday Laz Flash | J22: PDS (Mega)

Sheet Price Change- NFlash+FlashTB TH
B1: Type of Input required | C1: *Mandatory Fields
C2: Optional Fields
C3: Dropdown
C4: Autofill
B5: *Please take note for any input with double pricing with same date/duration, SVC will submit the lowest price
Q16: PLANNING BY CAMPAIGN Name PLEASE SELECT CAMPAIGN NAME, CAMPAIGN TYPE & CAMPAIGN TIERING
Q17: Campaign Name* | R17: Campaign 1 | T17: Campaign Name* | U17: Campaign 2 | W17: Campaign Name* | X17: Campaign 3 | Z17: Campaign Name* | AA17: Campaign 4
Q18: Campaign Type | R18: SMG | T18: Campaign Type | U18: A+ | W18: Campaign Type | X18: BAU | Z18: Campaign Type | AA18: SMG
Q19: Campaign Tiering | R19: 1 | T19: Campaign Tiering | U19: 2 | W19: Campaign Tiering | X19: 3 | Z19: Campaign Tiering | AA19: 1
Q20: Start Date | R20: 45383 | T20: Date | U20: {=IFERROR(_xlfn.TEXTJOIN(", ", TRUE, IF((U$17='Campaign Calendar'!$I$11:$I$45)*(U$18='Campaign Calendar'!$J$11:$J$45)*(U$19='Campaign Calendar'!$K$11:$K$45),'Campaign Calendar'!#REF!, "")), "")} | W20: Date | X20: {=IFERROR(_xlfn.TEXTJOIN(", ", TRUE, IF((X$17='Campaign Calendar'!$I$11:$I$45)*(X$18='Campaign Calendar'!$J$11:$J$45)*(X$19='Campaign Calendar'!$K$11:$K$45),'Campaign Calendar'!#REF!, "")), "")} | Z20: Date | AA20: {=IFERROR(_xlfn.TEXTJOIN(", ", TRUE, IF((AA$17='Campaign Calendar'!$I$11:$I$45)*(AA$18='Campaign Calendar'!$J$11:$J$45)*(AA$19='Campaign Calendar'!$K$11:$K$45),'Campaign Calendar'!#REF!, "")), "")}
Q21: End Date | R21: 04/04/2024 | T21: Date | U21: {=IFERROR(_xlfn.TEXTJOIN(", ", TRUE, IF((U$17='Campaign Calendar'!$I$11:$I$45)*(U$18='Campaign Calendar'!$J$11:$J$45)*(U$19='Campaign Calendar'!$K$11:$K$45),'Campaign Calendar'!#REF!, "")), "")} | W21: Date | X21: {=IFERROR(_xlfn.TEXTJOIN(", ", TRUE, IF((X$17='Campaign Calendar'!$I$11:$I$45)*(X$18='Campaign Calendar'!$J$11:$J$45)*(X$19='Campaign Calendar'!$K$11:$K$45),'Campaign Calendar'!#REF!, "")), "")} | Z21: Date | AA21: {=IFERROR(_xlfn.TEXTJOIN(", ", TRUE, IF((AA$17='Campaign Calendar'!$I$11:$I$45)*(AA$18='Campaign Calendar'!$J$11:$J$45)*(AA$19='Campaign Calendar'!$K$11:$K$45),'Campaign Calendar'!#REF!, "")), "")}
Q22: Start Time | R22: 00,00 | T22: Time | U22: {=IFERROR(_xlfn.TEXTJOIN(", ", TRUE, IF((U$17='Campaign Calendar'!$I$11:$I$45)*(U$18='Campaign Calendar'!$J$11:$J$45)*(U$19='Campaign Calendar'!$K$11:$K$45),'Campaign Calendar'!#REF!, "")), "")} | W22: Time | X22: {=IFERROR(_xlfn.TEXTJOIN(", ", TRUE, IF((X$17='Campaign Calendar'!$I$11:$I$45)*(X$18='Campaign Calendar'!$J$11:$J$45)*(X$19='Campaign Calendar'!$K$11:$K$45),'Campaign Calendar'!#REF!, "")), "")} | Z22: Time | AA22: {=IFERROR(_xlfn.TEXTJOIN(", ", TRUE, IF((AA$17='Campaign Calendar'!$I$11:$I$45)*(AA$18='Campaign Calendar'!$J$11:$J$45)*(AA$19='Campaign Calendar'!$K$11:$K$45),'Campaign Calendar'!#REF!, "")), "")}
Q23: End Time | R23: 02,00 | T23: Time | U23: {=IFERROR(_xlfn.TEXTJOIN(", ", TRUE, IF((U$17='Campaign Calendar'!$I$11:$I$45)*(U$18='Campaign Calendar'!$J$11:$J$45)*(U$19='Campaign Calendar'!$K$11:$K$45),'Campaign Calendar'!#REF!, "")), "")} | W23: Time | X23: {=IFERROR(_xlfn.TEXTJOIN(", ", TRUE, IF((X$17='Campaign Calendar'!$I$11:$I$45)*(X$18='Campaign Calendar'!$J$11:$J$45)*(X$19='Campaign Calendar'!$K$11:$K$45),'Campaign Calendar'!#REF!, "")), "")} | Z23: Time | AA23: {=IFERROR(_xlfn.TEXTJOIN(", ", TRUE, IF((AA$17='Campaign Calendar'!$I$11:$I$45)*(AA$18='Campaign Calendar'!$J$11:$J$45)*(AA$19='Campaign Calendar'!$K$11:$K$45),'Campaign Calendar'!#REF!, "")), "")}
Q24: Treasure Bowl Name* | T24: Treasure Bowl Name* | W24: Treasure Bowl Name* | Z24: Treasure Bowl Name*
Q25: Treasure Bowl ID* | T25: Treasure Bowl ID* | W25: Treasure Bowl ID* | Z25: Treasure Bowl ID*
Q26: Promotion Plan File/Folder* | R26: Share the relevant Link | T26: Promotion Plan File/Folder* | U26: Share the relevant Link | W26: Promotion Plan File/Folder* | X26: Share the relevant Link | Z26: Promotion Plan File/Folder* | AA26: Share the relevant Link
Q27: Relevant files for SVC | T27: Relevant files for SVC | W27: Relevant files for SVC | Z27: Relevant files for SVC
B28: EAN Code | C28: Product ID | D28: Variation ID | E28: Product Name | F28: Brand | G28: VBOM/Single/Bundle | H28: Product Url | I28: Lowest Sales Price(30day) | J28: Average Sales Price (30day) | K28: Lowest Onsite Price(30day) | L28: Average Onsite Price(30day) | M28: Category Name | N28: Lazada Recommend | O28: Stock | P28: L'Oreal recommended Price (list price) | Q28: Campaign Price | R28: Promo Discount % | S28: Tier | T28: Campaign Price | U28: Promo Discount % | V28: Tier | W28: Campaign Price | X28: Promo Discount % | Y28: Tier | Z28: Campaign Price | AA28: Promo Discount % | AB28: Tier
G29: Select from Dropdown
G30: Select from Dropdown
G31: Select from Dropdown
G32: Select from Dropdown
G33: Select from Dropdown
G34: Select from Dropdown
G35: Select from Dropdown
G36: Select from Dropdown
G37: Select from Dropdown
G38: Select from Dropdown
G39: Select from Dropdown
G40: Select from Dropdown
... G297: Select from Dropdown

Sheet Price Change - draft
B1: Type of Input require | C1: *Mandatory Fields | F1: Changes done as per feedback
C2: Optional Fields
C3: Dropdown
B4: *Please take note for any input with double pricing with same date/duration, SVC will submit the lowest price
R13: Flash Sale Pricing
R14: Promotion Type: BAU | T14: Promotion Type: CP | V14: Promotion Type: MG | X14: Promotion Type: SMG
R15: Campaign Name* | S15: BAU | T15: Campaign Name* | U15: CP | V15: Campaign Name* | W15: MG | X15: Campaign Name* | Y15: SMG
R16: Campaign Type | T16: Campaign Type | V16: Campaign Type | X16: Campaign Type
R17: Campaign Tiering | T17: Campaign Tiering | V17: Campaign Tiering | X17: Campaign Tiering
R18: Platform | S18: Lazada | T18: Platform | U18: Lazada | V18: Platform | W18: Lazada | X18: Platform | Y18: Lazada
R19: Treasure Bowl Name* | T19: Treasure Bowl Name* | V19: Treasure Bowl Name* | X19: Treasure Bowl Name*
